Workbook
Name 外部資料_6: '範例檔案 (6)'!$A$1

Sheet 綜合損益表
A1: 會計科目 | B1: 2023 | C1: 2024 | D1: 2025
A2: 國外營運機構財務報表換算之兌換差額 | B2: -56379 | C2: 1753411 | D2: -1398320
A3: 採用權益法認列之關聯企業及合資之其他綜合損益之份額-不重分類至損益之項目 | B3: 7024 | C3: 17638 | D3: -15125
A4: 採用權益法認列之關聯企業及合資之其他綜合損益之份額-可能重分類至損益之項目 | B4: 3789 | C4: -4198 | D4: -815
A5: 確定福利計畫之再衡量數 | B5: -15228 | C5: 414552 | D5: 144199
A6: 與不重分類之項目相關之所得稅 | B6: -3763 | C6: 83565 | D6: 33415
A7: 透過其他綜合損益按公允價值衡量之權益工具投資未實現評價損益 | B7: 171930 | C7: 262718 | D7: 44471
A8: 其他利益及損失淨額 | B8: -157665 | C8: 150509 | D8: -129992
A9: 其他收入 | B9: 2372082 | C9: 2772141 | D9: 3425318
A10: 利息收入 | B10: 1569505 | C10: 1754562 | D10: 1463634
A11: 採用權益法認列之關聯企業及合資損益之份額淨額 | B11: 202535 | C11: 332347 | D11: 336556
A12: 推銷費用 | B12: 82457527 | C12: 88839517 | D12: 93677885
A13: 管理費用 | B13: 11927562 | C13: 12592666 | D13: 12929251
... A36: 繼續營業單位本期淨利（淨損） | B36: 12661131 | C36: 13741439 | D36: 13334282

Sheet 資產負債表
A1: 會計科目 | B1: 2023 | C1: 2024 | D1: 2025 | E1: 2022
A2: 國外營運機構財務報表換算之兌換差額 | B2: -649458 | C2: 1023558 | D2: -225133
A3: 普通股股本 | B3: 10396223 | C3: 10396223 | D3: 10396223
A4: 未分配盈餘（或待彌補虧損） | B4: 11939629 | C4: 13426603 | D4: 13744000
A5: 法定盈餘公積 | B5: 15302251 | C5: 16364599 | D5: 17549729
A6: 特別盈餘公積 | B6: 54625 | C6: 0
A7: 資本公積－其他 | B7: 90300 | C7: 91067 | D7: 91958
A8: 透過其他綜合損益按公允價值衡量之金融資產未實現評價損益 | B8: 710937 | C8: 975643 | D8: 1004660
A9: 不動產、廠房及設備 | B9: 37505212 | C9: 49670492 | D9: 62290649
A10: 使用權資產 | B10: 88197513 | C10: 91426317 | D10: 101115343
A11: 保留盈餘合計 | B11: 27296505 | C11: 29791202 | D11: 31293729
A12: 其他應付款 | B12: 33134376 | C12: 33714982 | D12: 36989148
A13: 其他應收款淨額 | B13: 3102494 | C13: 3752568 | D13: 3514966
A14: 其他權益合計 | B14: 61479 | C14: 1999201 | D14: 779527
A15: 其他流動負債 | B15: 3924950 | C15: 4324669 | D15: 3822965
A16: 其他流動資產 | B16: 2707993 | C16: 3134826 | D16: 2869961
A17: 其他非流動負債 | B17: 9184510 | C17: 8678934 | D17: 8650599
A18: 其他非流動資產 | B18: 5978511 | C18: 5152870 | D18: 5007590
... A20: 合約負債－非流動 | B20: 679083 | C20: 767848 | D20: 717924
A21: 存貨 | B21: 23427376 | C21: 23631957 | D21: 26709097 | E21: 21670453
A22: 應付帳款 | B22: 28401121 | C22: 30180289 | D22: 26667075
A23: 應付帳款－關係人 | B23: 3670965 | C23: 3951265 | D23: 4325672
A24: 應付短期票券 | B24: 3497090 | C24: 2098141 | D24: 6992539
A25: 應付票據 | B25: 2204719 | C25: 1047100 | D25: 967393
A26: 應收帳款淨額 | B26: 7340609 | C26: 7577551 | D26: 7617155
A27: 投資性不動產淨額 | B27: 3214862 | C27: 2899200 | D27: 1071791
A28: 按攤銷後成本衡量之金融資產－流動 | B28: 6978609 | C28: 181334 | D28: 391485
A29: 按攤銷後成本衡量之金融資產－非流動 | C29: 215593 | D29: 206895
A30: 採用權益法之投資 | B30: 13496300 | C30: 13746633 | D30: 13817711
A31: 本期所得稅負債 | B31: 2341093 | C31: 2331030 | D31: 2115688
A32: 本期所得稅資產 | B32: 8276 | C32: 6024 | D32: 12683
A33: 無形資產 | B33: 9508023 | C33: 9197116 | D33: 9249819
A34: 現金及約當現金 | B34: 48929582 | C34: 51267712 | D34: 50182134
A35: 短期借款 | B35: 9798343 | C35: 6492532 | D35: 12133459
A36: 租賃負債－流動 | B36: 14599887 | C36: 15340071 | D36: 16162821
A37: 租賃負債－非流動 | B37: 78066236 | C37: 80316561 | D37: 88713790
A38: 股本合計 | B38: 10396223 | C38: 10396223 | D38: 10396223
A39: 資本公積合計 | B39: 90300 | C39: 91067 | D39: 91958
A40: 透過其他綜合損益按公允價值衡量之金融資產－非流動 | B40: 1019411 | C40: 1282129 | D40: 1326600
A41: 透過損益按公允價值衡量之金融資產－流動 | B41: 943266 | C41: 1562588 | D41: 1308063
...

Sheet 現金流量表
A1: 會計科目 | B1: 2023 | C1: 2024 | D1: 2025
A2: 其他應付款增加（減少） | B2: 3791730 | C2: -1138830 | D2: 2718947
A3: 其他應收款（增加）減少 | B3: -271452 | C3: -437971 | D3: -64843
A4: 其他流動資產（增加）減少 | B4: 266640 | C4: -426833 | D4: 264865
A5: 合約負債增加（減少） | B5: 551842 | C5: 1129646 | D5: 551061
A6: 存貨減少(增加)之調整數 | B6: -1756923 | C6: -204581 | D6: -3077140
A7: 強制透過損益按公允價值衡量之金融資產（增加）減少 | B7: -398998 | C7: -596418 | D7: 388848
A8: 應付帳款增加（減少） | B8: 3229103 | C8: 2799558 | D8: -3138807
A9: 應付票據增加（減少） | B9: -473 | C9: -1157619 | D9: -79707
A10: 應收帳款（增加）減少 | B10: -676022 | C10: -320073 | D10: -43760
A11: 淨確定福利負債增加(減少) | B11: -144006 | C11: -185094 | D11: -43623
A12: 與營業活動相關之負債之淨變動合計 | B12: 7553338 | C12: 1893416 | D12: -78065
A13: 與營業活動相關之資產之淨變動合計 | B13: -2358134 | C13: -2048412 | D13: -2820680
... A26: 處分投資性不動產損失（利益） | B26: 365 | C26: -1835 | D26: -3742
A27: 處分採用權益法之投資損失（利益） | C27: -292954 | D27: 0
A28: 透過損益按公允價值衡量金融資產及負債之淨損失（利益） | B28: -13078 | C28: -22904 | D28: -134323
A29: 非金融資產減損損失 | D29: 48574
A30: 預期信用減損損失（利益）數∕呆帳費用提列（轉列收入）數 | B30: 36661 | C30: 22832 | D30: 4156
A31: 調整項目合計 | B31: 28489478 | C31: 23918400 | D31: 23692036
A32: 償還長期借款 | B32: -365539 | C32: -36101245 | D32: -51033846
A33: 其他投資活動 | D33: 172994
A34: 其他籌資活動 | B34: -302 | C34: -181 | D34: -118
A35: 其他非流動負債增加 | B35: 26981 | C35: 664 | D35: 162975
A36: 其他非流動負債減少 | B36: 0
A37: 其他非流動資產增加 | B37: -950903 | C37: 0
A38: 其他非流動資產減少 | C38: 146916 | D38: 163652
A39: 取得不動產、廠房及設備 | B39: -12565647 | C39: -14652109 | D39: -17062400
A40: 取得子公司股權 | B40: 0 | D40: -524254
A41: 取得投資性不動產 | B41: -428782 | C41: 0
A42: 取得按攤銷後成本衡量之金融資產 | B42: -6978609 | C42: -219974 | D42: -294617
A43: 取得採用權益法之投資 | B43: -5442963 | C43: 0
A44: 取得無形資產 | B44: -446732 | C44: -345625 | D44: -685241
A45: 存入保證金增加 | B45: 242016 | C45: 10246 | D45: -60506
A46: 存入保證金減少 | D46: 0
A47: 存出保證金增加 | B47: -180075 | C47: -365472 | D47: -155575
A48: 應付短期票券增加 | B48: 3497090 | C48: 22234373 | D48: 74929915
A49: 應付短期票券減少 | C49: -23633322 | D49: -70035517
A50: 投資活動之淨現金流入（流出） | B50: -27008873 | C50: -12838481 | D50: -21838846
A51: 支付之利息 | B51: -1379605 | C51: -1620603 | D51: -2080699
A52: 收取之利息 | B52: 1492773 | C52: 1517041 | D52: 1593085
...

Sheet 財務比率計算
A1: 財務比率 | B1: 2023 | C1: 2024 | D1: 2025
A2: 毛利率 | B2: =_xlfn.XLOOKUP("營業毛利（毛損）淨額",綜合損益表[會計科目],綜合損益表[2023],0)/_xlfn.XLOOKUP("營業收入合計",綜合損益表[會計科目],綜合損益表[2023],0) -> 0.34119226 | C2: =_xlfn.XLOOKUP("營業毛利（毛損）淨額",綜合損益表[會計科目],綜合損益表[2024],0)/_xlfn.XLOOKUP("營業收入合計",綜合損益表[會計科目],綜合損益表[2024],0) -> 0.34157054 | D2: =_xlfn.XLOOKUP("營業毛利（毛損）淨額",綜合損益表[會計科目],綜合損益表[2025],0)/_xlfn.XLOOKUP("營業收入合計",綜合損益表[會計科目],綜合損益表[2025],0) -> 0.34368243
A3: 營業利益率 | B3: =_xlfn.XLOOKUP("營業利益（損失）",綜合損益表[會計科目],綜合損益表[2023],0)/_xlfn.XLOOKUP("營業收入合計",綜合損益表[會計科目],綜合損益表[2023],0) -> 0.04337117 | C3: =_xlfn.XLOOKUP("營業利益（損失）",綜合損益表[會計科目],綜合損益表[2024],0)/_xlfn.XLOOKUP("營業收入合計",綜合損益表[會計科目],綜合損益表[2024],0) -> 0.041347723 | D3: =_xlfn.XLOOKUP("營業利益（損失）",綜合損益表[會計科目],綜合損益表[2025],0)/_xlfn.XLOOKUP("營業收入合計",綜合損益表[會計科目],綜合損益表[2025],0) -> 0.03971671
A4: 淨利率 | B4: =_xlfn.XLOOKUP("本期淨利（淨損）",綜合損益表[會計科目],綜合損益表[2023],0)/_xlfn.XLOOKUP("營業收入合計",綜合損益表[會計科目],綜合損益表[2023],0) -> 0.039935204 | C4: =_xlfn.XLOOKUP("本期淨利（淨損）",綜合損益表[會計科目],綜合損益表[2024],0)/_xlfn.XLOOKUP("營業收入合計",綜合損益表[會計科目],綜合損益表[2024],0) -> 0.040663278 | D4: =_xlfn.XLOOKUP("本期淨利（淨損）",綜合損益表[會計科目],綜合損益表[2025],0)/_xlfn.XLOOKUP("營業收入合計",綜合損益表[會計科目],綜合損益表[2025],0) -> 0.038018155
A5: ROE | B5: =_xlfn.XLOOKUP(綜合損益表!$A$28,綜合損益表!$A:$A,綜合損益表!B:B,0)/_xlfn.XLOOKUP(資產負債表!$A$53,資產負債表!$A:$A,資產負債表!B:B,0) -> 0.26461482 | C5: =_xlfn.XLOOKUP(綜合損益表!$A$28,綜合損益表!$A:$A,綜合損益表!C:C,0)/_xlfn.XLOOKUP(資產負債表!$A$53,資產負債表!$A:$A,資產負債表!C:C,0) -> 0.2641535 | D5: =_xlfn.XLOOKUP(綜合損益表!$A$28,綜合損益表!$A:$A,綜合損益表!D:D,0)/_xlfn.XLOOKUP(資產負債表!$A$53,資產負債表!$A:$A,資產負債表!D:D,0) -> 0.25193931
A6: ROA | B6: =_xlfn.XLOOKUP(綜合損益表!$A$28,綜合損益表!$A:$A,綜合損益表!B:B,0)/_xlfn.XLOOKUP(資產負債表!$A$57,資產負債表!$A:$A,資產負債表!B:B,0) -> 0.049197627 | C6: =_xlfn.XLOOKUP(綜合損益表!$A$28,綜合損益表!$A:$A,綜合損益表!C:C,0)/_xlfn.XLOOKUP(資產負債表!$A$57,資產負債表!$A:$A,資產負債表!C:C,0) -> 0.050935292 | D6: =_xlfn.XLOOKUP(綜合損益表!$A$28,綜合損益表!$A:$A,綜合損益表!D:D,0)/_xlfn.XLOOKUP(資產負債表!$A$57,資產負債表!$A:$A,資產負債表!D:D,0) -> 0.045566939
A7: 負債比率 | B7: =_xlfn.XLOOKUP(資產負債表!$A$56,資產負債表!$A:$A,資產負債表!B:B,0)/_xlfn.XLOOKUP(資產負債表!$A$57,資產負債表!$A:$A,資產負債表!B:B,0) -> 0.81407834 | C7: =_xlfn.XLOOKUP(資產負債表!$A$56,資產負債表!$A:$A,資產負債表!C:C,0)/_xlfn.XLOOKUP(資產負債表!$A$57,資產負債表!$A:$A,資產負債表!C:C,0) -> 0.80717541 | D7: =_xlfn.XLOOKUP(資產負債表!$A$56,資產負債表!$A:$A,資產負債表!D:D,0)/_xlfn.XLOOKUP(資產負債表!$A$57,資產負債表!$A:$A,資產負債表!D:D,0) -> 0.81913526
A8: 流動比率 | B8: =_xlfn.XLOOKUP(資產負債表!$A$49,資產負債表!$A:$A,資產負債表!B:B,0)/_xlfn.XLOOKUP(資產負債表!$A$48,資產負債表!$A:$A,資產負債表!B:B,0) -> 0.87291805 | C8: =_xlfn.XLOOKUP(資產負債表!$A$49,資產負債表!$A:$A,資產負債表!C:C,0)/_xlfn.XLOOKUP(資產負債表!$A$48,資產負債表!$A:$A,資產負債表!C:C,0) -> 0.860783 | D8: =_xlfn.XLOOKUP(資產負債表!$A$49,資產負債表!$A:$A,資產負債表!D:D,0)/_xlfn.XLOOKUP(資產負債表!$A$48,資產負債表!$A:$A,資產負債表!D:D,0) -> 0.78398348
A9: 存貨週轉次數 | B9: =_xlfn.XLOOKUP(綜合損益表!$A$31,綜合損益表!$A:$A,綜合損益表!B:B,0)/_xlfn.XLOOKUP(資產負債表!$A$59,資產負債表!$A:$A,資產負債表!B:B,0) -> 9.2629571 | C9: =_xlfn.XLOOKUP(綜合損益表!$A$31,綜合損益表!$A:$A,綜合損益表!C:C,0)/_xlfn.XLOOKUP(資產負債表!$A$59,資產負債表!$A:$A,資產負債表!C:C,0) -> 9.4563451 | D9: =_xlfn.XLOOKUP(綜合損益表!$A$31,綜合損益表!$A:$A,綜合損益表!D:D,0)/_xlfn.XLOOKUP(資產負債表!$A$59,資產負債表!$A:$A,資產負債表!D:D,0) -> 9.1453498

Sheet 財務比率
A1: 毛利率 | B1: 2023 | C1: 0.34119226
A2: 毛利率 | B2: 2024 | C2: 0.34157054
A3: 毛利率 | B3: 2025 | C3: 0.34368243
A4: 營業利益率 | B4: 2023 | C4: 0.04337117
A5: 營業利益率 | B5: 2024 | C5: 0.041347723
A6: 營業利益率 | B6: 2025 | C6: 0.03971671
A7: 淨利率 | B7: 2023 | C7: 0.039935204
A8: 淨利率 | B8: 2024 | C8: 0.040663278
A9: 淨利率 | B9: 2025 | C9: 0.038018155
A10: ROE | B10: 2023 | C10: 0.26461482
A11: ROE | B11: 2024 | C11: 0.2641535
A12: ROE | B12: 2025 | C12: 0.25193931
... A24: 存貨週轉次數 | B24: 2025 | C24: 9.1453498

Sheet YoY 比較
A1: YoY 變動分析
A2: 財務比率 | B2: 2023→2024 | C2: 2024→2025
A3: 毛利率 | B3: =(財務比率計算!C2-財務比率計算!B2)/財務比率計算!B2 -> 0.0011086952 | C3: =(財務比率計算!D2-財務比率計算!C2)/財務比率計算!C2 -> 0.0061828882
A4: 營業利益率 | B4: =(財務比率計算!C3-財務比率計算!B3)/財務比率計算!B3 -> -0.046654194 | C4: =(財務比率計算!D3-財務比率計算!C3)/財務比率計算!C3 -> -0.039446252
A5: 淨利率 | B5: =(財務比率計算!C4-財務比率計算!B4)/財務比率計算!B4 -> 0.018231392 | C5: =(財務比率計算!D4-財務比率計算!C4)/財務比率計算!C4 -> -0.065049431
A6: ROE | B6: =(財務比率計算!C5-財務比率計算!B5)/財務比率計算!B5 -> -0.0017433448 | C6: =(財務比率計算!D5-財務比率計算!C5)/財務比率計算!C5 -> -0.046238977
A7: ROA | B7: =(財務比率計算!C6-財務比率計算!B6)/財務比率計算!B6 -> 0.035320088 | C7: =(財務比率計算!D6-財務比率計算!C6)/財務比率計算!C6 -> -0.10539554
A8: 負債比率 | B8: =(財務比率計算!C7-財務比率計算!B7)/財務比率計算!B7 -> -0.008479441 | C8: =(財務比率計算!D7-財務比率計算!C7)/財務比率計算!C7 -> 0.014816918
A9: 流動比率 | B9: =(財務比率計算!C8-財務比率計算!B8)/財務比率計算!B8 -> -0.013901714 | C9: =(財務比率計算!D8-財務比率計算!C8)/財務比率計算!C8 -> -0.089220535
A10: 存貨週轉次數 | B10: =(財務比率計算!C9-財務比率計算!B9)/財務比率計算!B9 -> 0.020877567 | C10: =(財務比率計算!D9-財務比率計算!C9)/財務比率計算!C9 -> -0.032887472

Sheet 範例檔案 (6)
A1: 外部資料_6

Sheet 綜合損益表 for sql
A1: 科目名稱 | B1: 年度 | C1: 金額
A2: 營業收入合計 | B2: 2023 | C2: 317041854
A3: 營業成本合計 | B3: 2023 | C3: 208869628
A4: 營業毛利（毛損） | B4: 2023 | C4: 108172226
A5: 營業毛利（毛損）淨額 | B5: 2023 | C5: 108172226
A6: 推銷費用 | B6: 2023 | C6: 82457527
A7: 管理費用 | B7: 2023 | C7: 11927562
A8: 預期信用減損損失（利益） | B8: 2023 | C8: 36661
A9: 營業費用合計 | B9: 2023 | C9: 94421750
A10: 營業利益（損失） | B10: 2023 | C10: 13750476
A11: 利息收入 | B11: 2023 | C11: 1569505
A12: 其他收入 | B12: 2023 | C12: 2372082
A13: 其他利益及損失淨額 | B13: 2023 | C13: -157665
... A112: 稀釋每股盈餘 | B112: 2025 | C112: 10.75

Sheet 資產負債表 for sql
A1: 科目名稱 | B1: 年度 | C1: 金額
A2: 現金及約當現金 | B2: 2023 | C2: 48929582
A3: 透過損益按公允價值衡量之金融資產－流動 | B3: 2023 | C3: 943266
A4: 按攤銷後成本衡量之金融資產－流動 | B4: 2023 | C4: 6978609
A5: 應收帳款淨額 | B5: 2023 | C5: 7340609
A6: 其他應收款淨額 | B6: 2023 | C6: 3102494
A7: 本期所得稅資產 | B7: 2023 | C7: 8276
A8: 存貨 | B8: 2023 | C8: 23427376
A9: 預付款項 | B9: 2023 | C9: 1608202
A10: 其他流動資產 | B10: 2023 | C10: 2707993
A11: 流動資產合計 | B11: 2023 | C11: 95046407
A12: 透過損益按公允價值衡量之金融資產－非流動 | B12: 2023 | C12: 85480
A13: 透過其他綜合損益按公允價值衡量之金融資產－非流動 | B13: 2023 | C13: 1019411
... A170: 母公司暨子公司所持有之母公司庫藏股股數（單位：股） | B170: 2025 | C170: 0

Sheet 現金流量表 for sql
A1: 科目名稱 | B1: 年度 | C1: 金額
A2: 繼續營業單位稅前淨利（淨損） | B2: 2023 | C2: 16357359
A3: 本期稅前淨利（淨損） | B3: 2023 | C3: 16357359
A4: 折舊費用 | B4: 2023 | C4: 23045062
A5: 攤銷費用 | B5: 2023 | C5: 711751
A6: 預期信用減損損失（利益）數∕呆帳費用提列（轉列收入）數 | B6: 2023 | C6: 36661
A7: 透過損益按公允價值衡量金融資產及負債之淨損失（利益） | B7: 2023 | C7: -13078
A8: 利息費用 | B8: 2023 | C8: 1379574
A9: 利息收入 | B9: 2023 | C9: -1569505
A10: 股利收入 | B10: 2023 | C10: -53884
A11: 採用權益法認列之關聯企業及合資損失（利益）之份額 | B11: 2023 | C11: -202535
A12: 處分及報廢不動產、廠房及設備損失（利益） | B12: 2023 | C12: 62045
A13: 處分投資性不動產損失（利益） | B13: 2023 | C13: 365
... A205: 資產負債表帳列之現金及約當現金 | B205: 2025 | C205: 50182134
